Workbook

Sheet Geral
A1: Código | B1: Disciplina | C1: Conteudista | D1: DI | E1: Número de semanas | F1: Videoaulas | G1: Bim
A2: PJI610 | B2: Projeto Integrador em Computação VI | C2: Marcelo Garcia Manzato | D2: Alfredo | E2: 7 | F2: (1-7) | G2: 2024.1
A3: PJI420 | B3: Projeto Integrador I - Negócios e Produção | C3: Antonio Francisco Savi | D3: Alfredo | E3: 7 | F3: (1-7) | G3: 2024.1
A4: ADM310 | B4: Estratégia e Governança | C4: Bruna Liria Avelhan | D4: Fábio | E4: 8 | F4: (11-21) | G4: 2024.1
A5: DIR300 | B5: Noções básicas de direito público e privado | C5: Luciana Lopes Canavez | D5: Juliana | E5: 8 | F5: (11-21) | G5: 2024.1
A6: COM311 | B6: Desenho Técnico Assistido por Computador | C6: Antonio Francisco Savi | D6: Daniel | E6: 8 | F6: (11-21) | G6: 2024.1
A7: SDD001 | B7: Didática | C7: Simone Telles | D7: Claudia | E7: 8 | F7: (11-21) | G7: 2024.1
A8: SFH001 | B8: Fundamentos Históricos, Filosóficos e Sociológicos da Educação | C8: Eli Vagner Francisco Rodrigues | D8: Ieda | E8: 8 | F8: (11-21) | G8: 2024.1
A9: COM590 | B9: Compiladores | C9: Júlio Cezar Estrella | D9: Fábio | E9: 8 | F9: (11-21) | G9: 2024.2
A10: ADM330 | B10: Conceitos e práticas de marketing | C10: Renato da Costa dos Santos | D10: Fábia | E10: 8 | F10: (11-21) | G10: 2024.2
A11: ADM320 | B11: Gestão da Produção e Operações | C11: Renato da Costa dos Santos | D11: Mirtes | E11: 8 | F11: (11-21) | G11: 2024.2
A12: PES320 | B12: Controle Estatístico e Gestão da Qualidade | C12: Marco Aurélio Soares De Castro | D12: Rafael | E12: 8 | F12: (11-21) | G12: 2024.2
A13: SAA001 | B13: Avaliação Educacional e da Aprendizagem | C13: Eric Ferdinando Kanai Passone | D13: Renata | E13: 8 | F13: (11-21) | G13: 2024.2
... A24: PJI120 | B24: Projeto Integrador - Adaptação curricular | C24: Mônica | D24: Alfredo | E24: 7 | F24: (1-7) | G24: 2024.3
A25: MAT300 | B25: Fundamentos da Matemática Elementar | D25: Rafael | E25: 8 | F25: (11-21) | G25: 2024.3
A26: COM100 | B26: Pensamento Computacional | C26: Marcos Borges | G26: 2024.3
A27: ADM300 | B27: Legislação e Responsabilidade Profissional | C27: Juliana Novi | D27: Fábio | E27: 8 | F27: (11-21) | G27: 2024.4
A28: SEJ001 | B28: Educação de Jovens e Adultos | C28: Adriana Batista de Souza Koide | D28: Juliana | E28: 8 | F28: (11-21) | G28: 2024.4
A29: CIN300 | B29: Gestão de Sistemas de Informação | C29: Antonio Francisco Savi | D29: Daniel | E29: 8 | F29: (11-21) | G29: 2024.4
A30: ADM370 | B30: Marketing Digital | C30: Marina Toledo Lourenção Rocha | D30: Fábia | E30: 8 | F30: (11-21) | G30: 2024.4
A31: EPR310 | B31: Pesquisa Operacional II | C31: Anibal Tavares De Azevedo | D31: Ieda | E31: 8 | F31: (11-21) | G31: 2024.4
A32: ADM360 | B32: Análise e modelagem de processos | C32: Renato da Costa dos Santos | D32: Joel | E32: 8 | F32: (11-21) | G32: 2024.4
A33: HFE001 | B33: Filosofia da Educação | C33: Ronildo Alves Dos Santos | D33: autoinstrucional | E33: 8 | F33: (11-21) | G33: 2024.4
A34: HSE001 | B34: Sociologia da Educação | C34: Eli Vagner Francisco Rodrigues | D34: autoinstrucional | E34: 8 | F34: (11-21) | G34: 2024.4
A35: LET340 | B35: Gramática de Língua Portuguesa: morfologia | D35: Raquel/Cláudia | E35: 8 | F35: (11-21) | G35: 2024.4
A36: MAT310 | B36: Geometria Analítica | C36: Glauce Barbosa Verao | D36: Raquel | E36: 8 | F36: (11-21) | G36: 2024.4
A37: MMB002 | B37: Matemática básica | C37: Prof.Rúbia Barcelos Amaral | E37: 8 | F37: (11-21) | G37: 2024.2 AC
A38: FIS300 | B38: Física do Movimento (Engenharia de Computação 2020.1) | E38: 8 | F38: (11-21) | G38: 2024.2 AC
A39: EDU310 | B39: Letramento em LIBRAS para professores | C39: Karina Soledad Maldonado Molina | E39: 8 | F39: (11-21) | G39: 2024.3 AC
A40: SFI002 | B40: Fundamentos da Educação Infantil II | C40: Claudia Panizzolo | G40: 2024.3 AC
A41: TPL504 | B41: Projeto Integrador para Licenciatura IV | C41: Taitiâny Kárita Bonzanini | G41: 2024.3 AC
A42: LET320 | B42: Literatura e Cultura Brasileira | C42: Marise Soares Hansen | E42: 8 | F42: (11-21) | G42: 2024.3 AC
A43: LIN310 | B43: Aquisição da Linguagem: Oralidade e Escrita | C43: Lúcia Regiane Lopes-Damasio | E43: 8 | F43: (11-21) | G43: 2024.3 AC
A44: COM390 | B44: Engenharia de Software | G44: 2024.3 AC
A45: PJI240 | B45: Projeto Integrador em Computação II | G45: 2024.3 AC
A46: LET110 | B46: Leitura e Produção de textos | C46: Vanessa Martins do Monte | G46: 2024.3 AC
A47: SOC100 | B47: Ética, cidadania e Sociedade | C47: Eli Vagner Francisco Rodrigues | G47: 2024.3 AC
A48: EDU320 | B48: Educação Mediada por Tecnologias | C48: Raquel Rosan Christino Gitahy | E48: 8 | F48: (11-21) | G48: 2024.4 AC
A49: SMA001 | B49: Metodologias Ativas de Aprendizagem: Projetos Interdisciplinares | C49: Adriana Bauer | E49: 8 | F49: (11-21) | G49: 2024.4 AC
A50: LET330 | B50: Gramática de Língua Portuguesa II | C50: Lúcia Regiane Lopes-Damasio | E50: 8 | F50: (11-21) | G50: 2024.4 AC
...

Sheet 2024.1
A1: CÓD | B1: Disciplina | C1: Semanas | D1: Nº de aulas | E1: Título da aula | F1: Sinopse da Videoaula | G1: Link no YouTube | H1: Slide na pasta | I1: Status | J1: Download | K1: ID (TV Cultura) | L1: Duração | M1: Professor | N1: DI
A2: PJI610 | B2: Projeto Integrador em Computação VI | C2: Quinzena 1 | D2: AULA 01 | E2: Apresentação | G2: https://youtu.be/ZNFk0kUyd3w | H2: ok | I2: finalizado | J2: ok | K2: 2390P013365 | L2: 0.010497685 | M2: =VLOOKUP(A2,Geral!$A$1:$D$36,3,FALSE) -> Marcelo Garcia Manzato
D3: AULA 02 | E3: Plano de Negócios | G3: https://youtu.be/8puMOD6z8sc | H3: ok | I3: finalizado | J3: ok | K3: 2390P013366 | L3: 0.011759259
C4: Quinzena 3 | D4: AULA 03 | E4: Desenvolvimento Mobile | G4: https://youtu.be/J7I7vDCjVWM | H4: ok | I4: finalizado | J4: ok | K4: 2390P013367 | L4: 0.014050926
D5: AULA 04 | E5: Processamento digital de sinais | G5: https://youtu.be/K9v1J8KY760 | H5: ok | I5: finalizado | J5: ok | K5: 2390P013368 | L5: 0.013506944
C6: Quinzena 4 | D6: AULA 05 | E6: Internet das Coisas | G6: https://youtu.be/YRoWxDfcLXU | H6: ok | I6: finalizado | J6: ok | K6: 2390P013369 | L6: 0.011851852
D7: AULA 06 | E7: Sistemas Embarcados | G7: https://youtu.be/aKfI06JSc0M | H7: ok | I7: finalizado | J7: ok | K7: 2390P013370 | L7: 0.012141204
C8: Quinzena 6 | D8: AULA 07 | E8: Interface com usuário | G8: https://youtu.be/Ws3QP7nEfeI | H8: ok | I8: finalizado | J8: ok | K8: 2390P013371 | L8: 0.013993056
A10: PJI420 | B10: Projeto Integrador I - Negócios e Produção | C10: Quinzena 1 | D10: AULA 0 | E10: Apresentação | G10: https://youtu.be/9hYte8fBE8M | H10: ok | I10: finalizado | J10: ok | K10: 2390P013597 | L10: 0.0018518519
D11: AULA 01 | E11: Resumo geral do Projeto Integrador | G11: https://youtu.be/IH6uEr7bLcM | H11: ok | I11: finalizado | J11: ok | K11: 2390P013372 | L11: 0.012326389 | M11: =VLOOKUP(A10,Geral!$A$1:$D$36,3,FALSE) -> Antonio Francisco Savi
C12: Quinzena 2 | D12: AULA 02 | E12: Aproximação ao tema, escolha do local e observação in loco | G12: https://youtu.be/exBooQA-9_k | H12: ok | I12: finalizado | J12: ok | K12: 2390P013373 | L12: 0.0092361111
C13: Quinzena 3 | D13: AULA 03 | E13: Definição e estudo sobre o tema | G13: https://youtu.be/UD4mOD6V0Ys | H13: ok | I13: finalizado | J13: ok | K13: 2390P013374 | L13: 0.011759259
C14: Quinzena 4 | D14: AULA 04 | E14: Framework de processo e sistematização do projeto | G14: https://youtu.be/FvYKUueEtcY | H14: ok | I14: finalizado | J14: ok | K14: 2390P013375 | L14: 0.0094560185
C15: Quinzena 5 | D15: AULA 05 | E15: Gestão de projetos | G15: https://youtu.be/ohcPzmZ5gEI | H15: ok | I15: finalizado | J15: ok | K15: 2390P013376 | L15: 0.0095717593
C16: Quinzena 6 | D16: AULA 06 | E16: Ferramentas e métodos para confecção do protótipo | G16: https://youtu.be/c3yJPsBslwY | H16: ok | I16: finalizado | J16: ok | K16: 2390P013377 | L16: 0.0088888889
C17: Quinzena 7 | D17: AULA 07 | E17: Melhoria da solução | G17: https://youtu.be/R6babxG24H8 | H17: ok | I17: finalizado | J17: ok | K17: 2390P013378 | L17: 0.0088773148
A19: ADM310 | B19: Estratégia e Governança | C19: Semana 1 | D19: AULA 01 | E19: Estratégia empresarial: princípios e enfoques | G19: https://youtu.be/L2JM0shM98A | H19: OK | I19: finalizado | J19: ok | K19: 2390P013484 | L19: 0.013645833 | M19: =VLOOKUP(A19,Geral!$A$1:$D$36,3,FALSE) -> Bruna Liria Avelhan
D20: AULA 02 | E20: O modelo das 5 forças de Porter aplicado à Tecnologia da Informação | G20: https://youtu.be/VPsducNxa2U | H20: OK | I20: finalizado | J20: ok | K20: 2390P013485 | L20: 0.012673611
D21: AULA 03 | E21: Governança corporativa e governança de TI | G21: https://youtu.be/zLkn7c7PZpE | H21: OK | I21: finalizado | J21: ok | K21: 2390P013486 | L21: 0.014594907
C22: Semana 2 | D22: AULA 04 | E22: Planejamento estratégico da TI | G22: https://youtu.be/I6L_3W8HDq8 | H22: OK | I22: finalizado | J22: ok | K22: 2390P013487 | L22: 0.014097222
D23: AULA 05 | E23: Subsistemas de TI: objetivos e direcionamento | G23: https://youtu.be/54Ou0HYm2aw | H23: OK | I23: finalizado | J23: ok | K23: 2390P013488 | L23: 0.014016204
D24: AULA 06 | E24: Subsistemas de TI: Desenvolvimento e entrega | G24: https://youtu.be/pjHVT_frFis | H24: OK | I24: finalizado | J24: ok | K24: 2390P013489 | L24: 0.014108796
C25: Semana 3 | D25: AULA 07 | E25: Cobit: Introtução e Princípios-chaves | G25: https://youtu.be/-2qVeLe47mg | H25: OK | I25: finalizado | J25: ok | K25: 2390P013490 | L25: 0.015115741
D26: AULA 08 | E26: Cobit: Processos de TI e diretrizes de implantação | G26: https://youtu.be/xPDHyVqYjM8 | H26: OK | I26: finalizado | J26: ok | K26: 2390P013491 | L26: 0.015289352
D27: AULA 09 | E27: ITIL: Estratégia de Serviço | G27: https://youtu.be/0E2oP7PNRsg | H27: OK | I27: finalizado | J27: ok | K27: 2390P013492 | L27: 0.013726852
C28: Semana 4 | D28: AULA 10 | E28: ITIL: Desenho do serviço | G28: https://youtu.be/VIyr-n-YuuM | H28: OK | I28: finalizado | J28: ok | K28: 2390P013493 | L28: 0.014560185
D29: AULA 11 | E29: ITIL: Transição de serviço | G29: https://youtu.be/b7pVctSbCeA | H29: OK | I29: finalizado | J29: ok | K29: 2390P013494 | L29: 0.012777778
D30: AULA 12 | E30: ITIL: Operação de serviço e melhoria contínua de serviço | G30: https://youtu.be/dcQfk3oRYW8 | H30: OK | I30: finalizado | J30: ok | K30: 2390P013495 | L30: 0.01587963
C31: Semana 5 | D31: AULA 13 | E31: Governança de dados: as leis de proteção de dados | F31: Com chroma | G31: https://youtu.be/NsXKKE1E9Tw | H31: OK | I31: finalizado | J31: ok | K31: 2390P013496 | L31: 0.015902778
D32: AULA 14 | E32: Governança de dados: a ética nos dados | G32: https://youtu.be/Ah0prt98pSY | H32: OK | I32: finalizado | J32: ok | K32: 2390P013497 | L32: 0.014756944
D33: AULA 15 | E33: Governança de dados: metadados | F33: Com chroma | G33: https://youtu.be/aZLOEscPZCU | H33: OK | I33: finalizado | J33: ok | K33: 2390P013498 | L33: 0.013981481
C34: Semana 6 | D34: AULA 16 | E34: Arquitetura Corporativa | G34: https://youtu.be/v3arSFbHjLI | H34: OK | I34: finalizado | J34: ok | K34: 2390P013499 | L34: 0.012233796
B36: Noções básicas de direito público e privado | C36: Semana 1 | D36: AULA 0 | E36: Apresentação | G36: https://youtu.be/wtpp-lhPYu8 | H36: ok | I36: finalizado | J36: ok | K36: 2390P013670 | L36: 0.0018171296 | M36: Luciana Canavez
D37: AULA 01 | E37: Direito constitucional e administrativo | F37: Nesta videoaula, você conhecerá e compreenderá quais são as instituições e como é a estrutura do Estado, seus princípios constitucionais e as garantias fundamentais. | G37: https://youtu.be/8CgErP60jdQ | H37: ok | I37: finalizado | J37: ok | K37: 2390P013532 | L37: 0.015729167
D38: AULA 02 | E38: Noções de Direito Administrativo | F38: Nesta videoaula, você conhecerá e compreenderá os princípios e fundamentos da administração pública. | G38: https://youtu.be/n-Had_bjEJ0 | H38: ok | I38: finalizado | J38: ok | K38: 2390P013533 | L38: 0.023969907
C39: Semana 2 | D39: AULA 03 | E39: Das pessoas naturais e jurídicas | F39: Nesta videoaula, a Profª Luciana Lopes Canavez abordará todas as normas referentes às pessoas naturais, tratando de temas como capacidade e incapacidade, e os direitos da personalidade. Estudaremos ainda quem são as pessoas jurídicas de direito público e privado. | G39: https://youtu.be/sKvhRsGFnGU | H39: ok | I39: finalizado | J39: ok | K39: 2390P013534 | L39: 0.017106481
D40: AULA 04 | E40: Do negócio jurídico, das obrigações contratos e responsabilidade civil | F40: Nesta videoaula, analisaremos os requisitos para estabelecer negócios jurídicos, a forma como se estabelecem os vínculos obrigacionais e contratuais, por exemplo o contrato de compra e venda, e as responsabilidades decorrentes desses vínculos (contratual e extracontratual). | G40: https://youtu.be/LnqwJRGveEM | H40: ok | I40: finalizado | J40: ok | K40: 2390P013535 | L40: 0.017731481
D41: AULA 05 | E41: Do direito de propriedade e da posse | F41: Nesta videoaula, estudaremos os direitos de posse e de propriedade e as formas de manutenção e conservação desses direitos. | G41: https://youtu.be/cMdulMVLSo0 | H41: ok | I41: finalizado | J41: ok | K41: 2390P013918 | L41: 0.014699074
C42: Semana 3 | D42: AULA 06 | E42: Noções gerais de Direito Empresarial | F42: Nesta videoaula, a Profª Luciana Lopes Canavez abordará todos os conceitos iniciais do Direito Empresarial, tratará da capacidade de ser empresário, das responsabilidades e da perda da capacidade de empresário. | G42: https://youtu.be/wAqjZMY82zQ | H42: ok | I42: finalizado | J42: ok | K42: 2390P013537 | L42: 0.014560185
A43: DIR300 | D43: AULA 07 | E43: Das Sociedades | F43: Nesta videoaula, analisaremos as sociedades personificadas e não personificadas, e trataremos dos tipos societários mais comuns, como a sociedade limitada, sociedade anônima e sociedade simples. | G43: https://youtu.be/RVWsz8pCPp0 | H43: ok | I43: finalizado | J43: ok | K43: 2390P013538 | L43: 0.01681713
...

Sheet 2024.2
A1: CÓD | B1: Disciplina | C1: Semanas | D1: Nº de aulas | E1: Título da aula | F1: Sinopse da Videoaula | G1: Link no YouTube | H1: Slide na pasta | I1: Status | J1: Download | K1: ID (TV Cultura) | L1: Duração | M1: Professor | N1: DI
A2: COM590 | B2: Compiladores | C2: Semana 1 | D2: AULA 0 | E2: Apresentação | G2: https://youtu.be/4_7ttKOawbY | H2: OK | I2: finalizado | J2: ok | K2: 2390P013671 | L2: 0.0034606481 | M2: =VLOOKUP(A2,Geral!$A$1:$D$36,3,FALSE) -> Júlio Cezar Estrella
D3: AULA 01 | E3: Introdução aos Compiladores - Parte 1 | G3: https://youtu.be/IO8L7ZcGIBE | H3: OK | I3: finalizado | J3: ok | K3: 2390P013672 | L3: 0.013726852
D4: AULA 02 | E4: Introdução aos Compiladores - Parte 2 | G4: https://youtu.be/-fUIAZslUec | H4: OK | I4: finalizado | J4: ok | K4: 2390P013673 | L4: 0.011805556
D5: AULA 03 | E5: Introdução aos Compiladores - Parte 3 | G5: https://youtu.be/jcsNH9g1eWY | H5: OK | I5: finalizado | J5: ok | K5: 2390P013674 | L5: 0.01525463
C6: Semana 2 | D6: AULA 04 | E6: Análise Léxica - Parte 1 | G6: https://youtu.be/7Il_3wWc1Ic | H6: OK | I6: finalizado | J6: ok | K6: 2390P013675 | L6: 0.011041667
D7: AULA 05 | E7: Análise Léxica - Parte 2 | G7: https://youtu.be/mSGgoxHj834 | H7: OK | I7: finalizado | J7: ok | K7: 2390P013676 | L7: 0.014456019
D8: AULA 06 | E8: Análise Sintática - Parte 1 | G8: https://youtu.be/-VNmgcnsseo | H8: OK | I8: finalizado | J8: ok | K8: 2390P013677 | L8: 0.010069444
C9: Semana 3 | D9: AULA 07 | E9: Análise Sintática - Parte 2 | G9: https://youtu.be/F3V7q1L-_WM | H9: OK | I9: finalizado | J9: ok | K9: 2390P013678 | L9: 0.011053241
D10: AULA 08 | E10: Gramáticas | G10: https://youtu.be/DSgAHKDxHt4 | H10: OK | I10: finalizado | J10: ok | K10: 2390P013679 | L10: 0.0128125
D11: AULA 09 | E11: Árvore de Derivação | G11: https://youtu.be/mvTLPr_yi9Q | H11: OK | I11: finalizado | J11: ok | K11: 2390P013680 | L11: 0.011469907
C12: Semana 4 | D12: AULA 10 | E12: Tipos de Análise e Algoritmos | G12: https://youtu.be/m_oCazmF9i8 | H12: OK | I12: finalizado | J12: ok | K12: 2390P013681 | L12: 0.00875
D13: AULA 11 | E13: Análise Sintática Descendente | G13: https://youtu.be/jdbqaNVLRU8 | H13: OK | I13: finalizado | J13: ok | K13: 2390P013682 | L13: 0.01193287
D14: AULA 12 | E14: Análise Sintática Ascendente | G14: https://youtu.be/1NcdHjsnyaM | H14: OK | I14: finalizado | J14: ok | K14: 2390P013683 | L14: 0.009537037
C15: Semana 5 | D15: AULA 13 | E15: Análise Semântica - Parte 1 | G15: https://youtu.be/IeBzkXhzLMg | H15: OK | I15: finalizado | J15: ok | K15: 2390P013684 | L15: 0.010069444
D16: AULA 14 | E16: Análise Semântica - Parte 2 | G16: https://youtu.be/NCs3Nl1ruaw | H16: OK | I16: finalizado | J16: ok | K16: 2390P013685 | L16: 0.0099421296
D17: AULA 15 | E17: Tabela de Símbolos | G17: https://youtu.be/Lbw2XSXdMfk | H17: OK | I17: finalizado | J17: ok | K17: 2390P013992 | L17: 0.013252315
C18: Semana 6 | D18: AULA 16 | E18: Geração de Código Intermedário - Parte 1 | G18: https://youtu.be/kprY66DRrfM | H18: OK | I18: finalizado | J18: ok | K18: 2390P013687 | L18: 0.011122685
D19: AULA 17 | E19: Geração de Código Intermedário - Parte 2 | G19: https://youtu.be/7-fRozxcnLs | H19: OK | I19: finalizado | J19: ok | K19: 2390P013688 | L19: 0.010960648
D20: AULA 18 | E20: Otimização de Código | G20: https://youtu.be/NIFbBdmXY7M | H20: OK | I20: finalizado | J20: ok | K20: 2390P013689 | L20: 0.012650463
C21: Semana 7 | D21: AULA 19 | E21: Gerenciamento de Memória | G21: https://youtu.be/saa-kImX_7Q | H21: OK | I21: finalizado | J21: ok | K21: 2390P013690 | L21: 0.013958333
D22: AULA 20 | E22: Exemplos de Otimização de Código | G22: https://youtu.be/ACFeqbGKm7s | H22: OK | I22: finalizado | J22: ok | K22: 2390P013691 | L22: 0.013101852
D23: AULA 21 | E23: Compiladores X Interpretadores | G23: https://youtu.be/_UW6zqpqUoM | H23: OK | I23: finalizado | J23: ok | K23: 2390P013692 | L23: 0.0097337963
A25: ADM330 | B25: Conceitos e práticas de marketing | C25: Semana 1 | D25: AULA 0 | E25: Apresentação | G25: https://youtu.be/bPCusHxXqwY | H25: OK | I25: finalizado | J25: ok | K25: 2390P013647 | L25: 0.001724537 | M25: =VLOOKUP(A25,Geral!$A$1:$D$36,3,FALSE) -> Renato da Costa dos Santos
D26: AULA 01 | E26: Fundamentos de Marketing | G26: https://youtu.be/VADtol1bGf8 | H26: OK | I26: finalizado | J26: ok | K26: 2390P014149 | L26: 0.0071296296
D27: AULA 02 | E27: Os 4Ps (produto, preço, praça e promoção). | G27: https://youtu.be/xmtxEj14A1c | H27: OK | I27: finalizado | J27: ok | K27: 2390P013599 | L27: 0.009212963
D28: AULA 03 | E28: Estratégias de segmentação de mercado e posicionamento. | G28: https://youtu.be/FfZ5G3bu-VM | H28: OK | I28: finalizado | J28: ok | K28: 2390P013600 | L28: 0.011041667
C29: Semana 2 | D29: AULA 04 | E29: Pesquisa de Mercado | G29: https://youtu.be/K8N3wtu00Ds | H29: OK | I29: finalizado | J29: ok | K29: 2390P013601 | L29: 0.012233796
D30: AULA 05 | E30: Técnicas de coleta e análise de dados no marketing | G30: https://youtu.be/6tscqcKxZnI | H30: OK | I30: finalizado | J30: ok | K30: 2390P013602 | L30: 0.0089699074
D31: AULA 06 | E31: Comportamento do consumidor e tendências de mercado | G31: https://youtu.be/WjQylXkNIAw | H31: OK | I31: finalizado | J31: ok | K31: 2390P013603 | L31: 0.012025463
C32: Semana 3 | D32: AULA 07 | E32: Marketing de busca | G32: https://youtu.be/9Lj-wIfZQ6M | H32: OK | I32: finalizado | J32: ok | K32: 2390P013604 | L32: 0.010219907
D33: AULA 08 | E33: O uso dos anúncios pagos | G33: https://youtu.be/W6PLmL27sPs | H33: OK | I33: finalizado | J33: ok | K33: 2390P013741 | L33: 0.011111111
D34: AULA 09 | E34: Estratégias de otimização de sites | G34: https://youtu.be/VDRvZgjcpVg | H34: OK | I34: finalizado | J34: ok | K34: 2390P013606 | L34: 0.0095486111
C35: Semana 4 | D35: AULA 10 | E35: Elaboração de um plano de marketing | G35: https://youtu.be/GvMV2xNMmNM | H35: OK | I35: finalizado | J35: ok | K35: 2390P014061 | L35: 0.010474537
D36: AULA 11 | E36: Identificação de metas e recursos | G36: https://youtu.be/Y0x4e96ZNmw | H36: OK | I36: finalizado | J36: ok | K36: 2390P013608 | L36: 0.010763889
D37: AULA 12 | E37: Monitoramento de desempenho | G37: https://youtu.be/p10EWseGumo | H37: OK | I37: finalizado | J37: ok | K37: 2390P013609 | L37: 0.0093402778
C38: Semana 5 | D38: AULA 13 | E38: Estratégias de marketing de serviços | G38: https://youtu.be/ZKbojGW9_So | H38: OK | I38: finalizado | J38: ok | K38: 2390P014150 | L38: 0.01130787
D39: AULA 14 | E39: Características do setor de serviços | G39: https://youtu.be/6xy1vpnkMYY | H39: OK | I39: finalizado | J39: ok | K39: 2390P014151 | L39: 0.011481481
D40: AULA 15 | E40: Marketing de relacionamento | G40: https://youtu.be/sCvG0WEIjDA | H40: OK | I40: finalizado | J40: ok | K40: 2390P014152 | L40: 0.0091898148
C41: Semana 6 | D41: AULA 16 | E41: Marketing tradicional e o marketing digital | F41: Com arte | G41: https://youtu.be/pmZ7y5W7AGg | H41: OK | I41: finalizado | J41: ok | K41: 2390P014590 | L41: 0.0077314815
...

Sheet 2024.3
A1: CÓD | B1: Disciplina | C1: Semanas | D1: Nº de aulas | E1: Título da aula | F1: Sinopse da Videoaula | G1: Link no YouTube | H1: Slide na pasta | I1: Status | J1: Download | K1: ID (TV Cultura) | L1: Duração | M1: Professor | N1: DI
A2: ADM400 | B2: =VLOOKUP(A2,Geral!$A$1:$D$36,2,FALSE) -> Cidades Inteligentes | C2: Semana 1 | D2: AULA 0 | E2: Apresentação | G2: https://youtu.be/IuAQUTz_wTg | I2: finalizado | J2: ok | K2: 2390P014529 | L2: 0.0021296296 | M2: =VLOOKUP(A2,Geral!$A$1:$D$36,3,FALSE) -> Júlio Cezar Estrella | N2: =VLOOKUP(A2,Geral!$A$1:$D$36,4,FALSE) -> Daniel
D3: AULA 01 | E3: O que é uma Cidade Inteligente | G3: https://youtu.be/D4LFTdym7Oc | H3: Ok | I3: finalizado | J3: ok | K3: 2390P015132 | L3: 0.014918981
D4: AULA 02 | E4: O Papel da Gestão Pública nas Cidades Inteligentes | G4: https://youtu.be/9UctkXhcZM8 | H4: Ok | I4: finalizado | J4: ok | K4: 2390P015133 | L4: 0.014016204
D5: AULA 03 | E5: Desafios em Aberto nas Cidades Inteligentes | G5: https://youtu.be/TXqfsocBNUg | H5: Ok | I5: finalizado | J5: ok | K5: 2390P015134 | L5: 0.011377315
C6: Semana 2 | D6: AULA 04 | E6: Dados Abertos: Conceitos Fundamentais e Exemplos de Aplicações | G6: https://youtu.be/Lo8GIm9Ley4 | H6: Ok | I6: finalizado | J6: ok | K6: 2390P015135 | L6: 0.011284722
D7: AULA 05 | E7: Interoperabilidade em Cidades Inteligentes – Parte 1 | G7: https://youtu.be/ivTUbwrvB88 | H7: Ok | I7: finalizado | J7: ok | K7: 2390P015136 | L7: 0.01375
D8: AULA 06 | E8: Interoperabilidade em Cidades Inteligentes – Parte 2 | G8: https://youtu.be/BbXMgBkLK-A | H8: Ok | I8: finalizado | J8: ok | K8: 2390P015137 | L8: 0.0099421296
C9: Semana 3 | D9: AULA 07 | E9: Introdução ao Conceito de Interdisciplinaridade | G9: https://youtu.be/N9thu-48Ck8 | H9: Ok | I9: finalizado | J9: ok | K9: 2390P015138 | L9: 0.013518519
D10: AULA 08 | E10: Casos Práticos de Colaboração em Projetos Urbanos | G10: https://youtu.be/eJ207ATMsf0 | H10: Ok | I10: finalizado | J10: ok | K10: 2390P015139 | L10: 0.01130787
D11: AULA 09 | E11: Estratégias para superar Desafios na Implementação Interdisciplinar | G11: https://youtu.be/6l2fCwAeEMQ | H11: Ok | I11: finalizado | J11: ok | K11: 2390P015140 | L11: 0.0072916667
C12: Semana 4 | D12: AULA 10 | E12: Princípios de Internet das Coisas e suas Aplicações | G12: https://youtu.be/IHgSqg6kIew | H12: Ok | I12: finalizado | J12: ok | K12: 2390P015141 | L12: 0.013796296
D13: AULA 11 | E13: BigData: Análise das Características e Importância na Gestão Urbana | G13: https://youtu.be/tkyqf8JuIww | H13: Ok | I13: finalizado | J13: ok | K13: 2390P015142 | L13: 0.013148148
D14: AULA 12 | E14: Sistemas Distribuídos: Estratégias para lidar com a Escalabilidade em Ambientes Urbanos | G14: https://youtu.be/JrwqwU8ZaPw | H14: Ok | I14: finalizado | J14: ok | K14: 2390P015143 | L14: 0.013865741
C15: Semana 5 | D15: AULA 13 | E15: Ferramentas de Gestão e a utilização no gerenciamento de cidades inteligentes | G15: https://youtu.be/7FXRwxJFj_E | H15: Ok | I15: finalizado | J15: ok | K15: 2390P015144 | L15: 0.014502315
D16: AULA 14 | E16: Ferramentas Computacionais para o desenvolvimento de soluções para Cidades Inteligentes - Parte 1 | G16: https://youtu.be/8pPRLC0UWNI | H16: Ok | I16: finalizado | J16: ok | K16: 2390P015145 | L16: 0.01349537
D17: AULA 15 | E17: Ferramentas Computacionais para o desenvolvimento de soluções para Cidades Inteligentes - Parte 2 | G17: https://youtu.be/60DzT5wx5Gg | H17: Ok | I17: finalizado | J17: ok | K17: 2390P015146 | L17: 0.013773148
C18: Semana 6 | D18: AULA 16 | E18: O que é Simulação: Visão geral dos conceitos básicos de simulação | G18: https://youtu.be/y7U1rtTaxLU | H18: Ok | I18: finalizado | J18: ok | K18: 2390P015147 | L18: 0.01099537
D19: AULA 17 | E19: Simulação em Larga Escala: Desafios e Benefícios | G19: https://youtu.be/UFZRB7X_tkA | H19: Ok | I19: finalizado | J19: ok | K19: 2390P015148 | L19: 0.011099537
D20: AULA 18 | E20: Simulação no Contexto do Planejamento Urbano | G20: https://youtu.be/6VLZh7zpQ_w | H20: Ok | I20: finalizado | J20: ok | K20: 2390P015149 | L20: 0.010081019
C21: Semana 7 | D21: AULA 19 | E21: Tecnologias em Cidades Inteligentes: sensores | G21: https://youtu.be/zbZL69eYsZg | H21: Ok | I21: finalizado | J21: ok | K21: 2390P015150 | L21: 0.014363426
D22: AULA 20 | E22: Tecnologias em Cidades Inteligentes: Computação em Nuvem | G22: https://youtu.be/vnXlIimJnVM | H22: Ok | I22: finalizado | J22: ok | K22: 2390P015151 | L22: 0.011331019
D23: AULA 21 | E23: Tecnologias em Cidades Inteligentes: Inteligência Artificial (IA) | G23: https://youtu.be/yRZqk-Ua6Zw | H23: Ok | I23: finalizado | J23: ok | K23: 2390P015152 | L23: 0.012592593
A25: SCN001 | B25: =VLOOKUP(A25,Geral!$A$1:$D$36,2,FALSE) -> Fundamentos e práticas no ensino de Ciências da Natureza | C25: Semana 1 | D25: AULA 0 | E25: Apresentação | G25: https://youtu.be/4KU7Whs3ZyE | H25: ok | I25: finalizado | J25: ok | K25: 2390P014308 | L25: 0.0016550926 | M25: =VLOOKUP(A25,Geral!$A$1:$D$36,3,FALSE) -> Juliana Hanna Leite El Ottra | N25: =VLOOKUP(A25,Geral!$A$1:$D$36,4,FALSE) -> Vanessa
D26: AULA 01 | E26: Introdução à ciência (parte I) | G26: https://youtu.be/v4P_zDx62L0 | H26: ok | I26: finalizado | J26: ok | K26: 2390P014309 | L26: 0.014548611
D27: AULA 02 | E27: Introdução à ciência (parte II) | G27: https://youtu.be/g-Q8j2aY-iw | H27: ok | I27: finalizado | J27: ok | K27: 2390P014601 | L27: 0.014479167
D28: AULA 03 | E28: O método científico e o ensino de ciências por investigação | G28: https://youtu.be/BlR0ANkVvX0 | H28: ok | I28: finalizado | J28: ok | K28: 2390P014310 | L28: 0.014652778
C29: Semana 2 | D29: AULA 04 | E29: O desenvolvimento histórico dos estudos astronômicos | G29: https://youtu.be/FnPBZu_lvp4 | H29: ok | I29: finalizado | J29: ok | K29: 2390P014311 | L29: 0.014479167
D30: AULA 05 | E30: O desenvolvimento histórico dos estudos astronômicos (parte II)/ a astronomia do século XXI | G30: https://youtu.be/KPDlU9U7K9g | H30: ok | I30: finalizado | J30: ok | K30: 2390P014312 | L30: 0.0146875
D31: AULA 06 | E31: A relação entre a ciência e a religião, e sua relação com mudanças de paradigmas científicos | G31: https://youtu.be/8uj92HEG9ag | H31: ok | I31: finalizado | J31: ok | K31: 2390P014602 | L31: 0.014930556
C32: Semana 3 | D32: AULA 07 | E32: As quatro perspectivas entre Ciência e Religião | G32: https://youtu.be/GZ9QGxY2sqc | H32: ok | I32: finalizado | J32: ok | K32: 2390P014603 | L32: 0.013715278
D33: AULA 08 | E33: O desenvolvimento da Ciências da Terra e os processos tectônicos | G33: https://youtu.be/eH_6jkGvZKQ | H33: ok | I33: finalizado | J33: ok | K33: 2390P014044 | L33: 0.013715278
D34: AULA 09 | E34: A geologia e o meio ambiente | G34: https://youtu.be/wY6BgOn5rP4 | H34: ok | I34: finalizado | J34: ok | K34: 2390P014045 | L34: 0.014131944
C35: Semana 4 | D35: AULA 10 | E35: O efeito estufa e as mudanças climáticas: Parte I - Problemas ambientais do século XXI e a relação com a Ciência e sociedade | G35: https://youtu.be/VDueqEGF09Y | H35: ok | I35: finalizado | J35: ok | K35: 2390P014046 | L35: 0.014386574
D36: AULA 11 | E36: Os recursos hídricos: Parte II - Problemas ambientais do século XXI e a relação com a Ciência e sociedade | G36: https://youtu.be/PLQCk6AbC_0 | H36: ok | I36: finalizado | J36: ok | K36: 2390P014604 | L36: 0.014618056
D37: AULA 12 | E37: O problema do lixo: Parte III - Problemas ambientais do século XXI e a relação com a Ciência e sociedade | G37: https://youtu.be/9Lu-iAlWs4Q | H37: ok | I37: finalizado | J37: ok | K37: 2390P014048 | L37: 0.014027778
C38: Semana 5 | D38: AULA 13 | E38: O desenvolvimento da Biologia Molecular e a compreensão da vida | G38: https://youtu.be/vU3qKI6-jhw | H38: ok | I38: finalizado | J38: ok | K38: 2390P014049 | L38: 0.013680556
D39: AULA 14 | E39: Biotecnologia e Bioética | G39: https://youtu.be/wzZGAZ7Zv40 | H39: ok | I39: finalizado | J39: ok | K39: 2390P014050 | L39: 0.014606481
C40: Semana 6 | D40: AULA 15 | E40: A leitura crítica de obras científicas | G40: https://youtu.be/1F44bW2j6wI | H40: ok | I40: finalizado | J40: ok | K40: 2390P014605 | L40: 0.014490741
D41: AULA 16 | E41: A comunicação científica | G41: https://youtu.be/bODgK7Cs5og | H41: ok | I41: finalizado | J41: ok | K41: 2390P014052 | L41: 0.014791667
...

Sheet 2024.4
A1: CÓD | B1: Disciplina | C1: Semanas | D1: Nº de aulas | E1: Título da aula | F1: Sinopse da Videoaula | G1: Link no YouTube | H1: Slide na pasta | I1: Status | J1: Download | K1: ID (TV Cultura) | L1: Duração | M1: Professor | N1: DI
A2: ADM300 | B2: =VLOOKUP(A2,Geral!$A$1:$D$36,2,FALSE) -> Legislação e Responsabilidade Profissional | C2: Semana 1 | D2: AULA 0 | E2: Apresentação | G2: https://youtu.be/Ryp3n8c34uQ | H2: ok | I2: finalizado | J2: ok | K2: 2390P013669 | L2: 0.0011921296 | M2: =VLOOKUP(A2,Geral!$A$1:$D$36,3,FALSE) -> Juliana Novi | N2: =VLOOKUP(A2,Geral!$A$1:$D$36,4,FALSE) -> Fábio
D3: AULA 01 | E3: Direito e Sociologia | G3: https://youtu.be/vyIbsQreoOg | H3: ok | I3: finalizado | J3: ok | K3: 2390P013619 | L3: 0.014386574
C4: Semana 2 | D4: AULA 02 | E4: Implicações jurídicas na vida profissional do engenheiro | F4: e | G4: https://youtu.be/LfiBxsqPyig | H4: ok | I4: finalizado | J4: ok | K4: 2390P015396 | L4: 0.014930556
C5: Semana 3 | D5: AULA 03 | E5: Cidadania e Direitos | G5: https://youtu.be/NcPJ-N-Q_X8 | H5: ok | I5: finalizado | J5: ok | K5: 2390P014598 | L5: 0.013113426
C6: Semana 4 | D6: AULA 04 | E6: Lei Geral de Proteção de Dados | G6: https://youtu.be/eRWQNq6E8SA | H6: ok | I6: finalizado | J6: ok | K6: 2390P013622 | L6: 0.014143519
C7: Semana 5 | D7: AULA 05 | E7: Propriedade Intelectual | G7: https://youtu.be/ZSsudXfl0AQ | H7: ok | I7: finalizado | J7: ok | K7: 2390P013623 | L7: 0.014803241
C8: Semana 6 | D8: AULA 06 | E8: Direito Digital e Internet | G8: https://youtu.be/WZ5qikB7RLo | H8: ok | I8: finalizado | J8: ok | K8: 2390P013621 | L8: 0.01193287
C9: Semana 7 | D9: AULA 07 | E9: Software e Licenças | G9: https://youtu.be/C_H8SvNRNig | H9: ok | I9: finalizado | J9: ok | K9: 2390P013625 | L9: 0.015381944
A11: SEJ001 | B11: =VLOOKUP(A11,Geral!$A$1:$D$36,2,FALSE) -> Educação de Jovens e Adultos | C11: Semana 1 | D11: AULA 0 | E11: Apresentação | G11: https://youtu.be/RBX-fIxKIzc | H11: ok | I11: finalizado | J11: ok | K11: 2390P013788 | L11: =VLOOKUP(A11,Geral!$A$1:$D$36,3,FALSE) -> Adriana Batista de Souza Koide | M11: 0.0034722222 | N11: =VLOOKUP(A11,Geral!$A$1:$D$36,4,FALSE) -> Juliana
D12: AULA 01 | E12: Histórico da educação de jovens e adultos no Brasil | F12: Nesta primeira videoaula, a Profª Adriana Batista de Souza Koide tratará sobre a definição contemporânea da EJA, construída sobre suas memórias históricas, entendendo-a como real espaço de educação formal, com políticas públicas específicas. | G12: https://youtu.be/eXQkTg2yu1E | H12: ok | I12: finalizado | J12: ok | K12: 2390P015382 | M12: 0.0078587963
D13: AULA 02 | E13: Marcos legais e políticas públicas para a Educação de Jovens e Adultos no Brasil | F13: Nesta videoaula, a Profª Adriana Batista de Souza Koide abordará marcos legais e políticas públicas que fundamentam e consolidam a Educação de Jovens e Adultos, destacando que a educação se faz ao longo da vida, em todos os espaços e em todas as relações. | G13: https://youtu.be/oS-NieQXpo0 | H13: ok | I13: finalizado | J13: ok | K13: 2390P015383 | M13: 0.009212963
C14: Semana 2 | D14: AULA 03 | E14: Alfabetização, letramento e cidadania para jovens e adultos | F14: A videoaula tem como objetivo propiciar a identificação do processo de alfabetização na perspectiva do letramento no contexto da Educação de Jovens e Adultos, dialogando com a compreensão de práticas e conceitos sobre como a alfabetização e o letramento estão relacionados à construção do conhecimento e com os impactos da escolarização na vida humana. | G14: https://youtu.be/Jvj7DPb081o | H14: ok | I14: finalizado | J14: ok | K14: 2390P013791 | M14: 0.0078819444
D15: AULA 04 | E15: Alfabetização científica e consciência crítica na educação de jovens e adultos | F15: A videoaula intenta fomentar a reflexão sobre práticas que desenvolvam a alfabetização científica e o letramento crítico nos estudantes adultos, bem como destaca as diferenças entre a consciência ingênua e a consciência crítica, discutindo acerca da relação entre alfabetização, letramento, cidadania e educação a partir das contribuições de Paulo Freire. | G15: https://youtu.be/I1NmnytpXAM | H15: ok | I15: finalizado | J15: ok | K15: 2390P013792 | M15: 0.0084606481
C16: Semana 3 | D16: AULA 05 | E16: Práticas pedagógicas e propostas didáticas para a educação de jovens e adultos | F16: A videoaula tem como objetivo propiciar a análise crítica das práticas e metodologias utilizadas na Educação de Jovens e Adultos, fomentando reflexões sobre a identificação e a aplicação de propostas didáticas adequadas ao público adulto. | G16: https://youtu.be/ZWNDyQO3Urw | H16: ok | I16: finalizado | J16: ok | K16: 2390P013793 | M16: 0.0069560185
D17: AULA 06 | E17: Seleção e análise de materiais e recursos educacionais para a Educação de Jovens e Adultos | F17: O propósito da videoaula está em propiciar reflexões sobre a identificação e possíveis aplicações de propostas didáticas adequadas ao público adulto. | G17: https://youtu.be/GWV0anu1knE | H17: ok | I17: finalizado | J17: ok | K17: 2390P013794 | M17: 0.010150463
D18: AULA 7 | E18: Alfabetização e Paulo Freire | F18: A proposta de reflexão da videoaula trata sobre as contribuições de Paulo Freire para a Educação de Jovens e Adultos, com enfoque sobre a transição de consciência: ingênua e crítica. | G18: https://youtu.be/WAHeVm3OA6g | H18: ok | I18: finalizado | J18: ok | K18: 2390P013795 | M18: 0.0059027778
C19: Semana 4 | D19: AULA 08 | E19: Currículo: propostas disciplinares e diversidade | F19: O foco da videoaula consiste em colocar em diálogo as práticas pedagógicas, a diversidade e o currículo para a Educação de Jovens e Adultos, verificando possibilidades inovadoras e especificidades das manifestações e abordagens do currículo. | G19: https://youtu.be/mi2nl3VEAcY | H19: ok | I19: finalizado | J19: ok | K19: 2390P016297 | M19: 0.0092592593
D20: AULA 09 | E20: Direitos Humanos e Interdisciplinaridade | F20: A videoaula tem como propósito instigar a reflexão sobre temas possivelmente relevantes para a discussão sobre currículo na Educação de Jovens e Adultos, por exemplo: cidadania, trabalho e saúde. A proposta de currículo também é aberta para o respeito à diversidade e aos direitos humanos. | G20: https://youtu.be/BSBcdbSsrAs | H20: ok | I20: finalizado | J20: ok | K20: 2390P013797 | M20: 0.012164352
D21: AULA 10 | E21: As Demandas da Educação de Jovens e Adultos e algumas proposições da Neurociência | F21: Adaptação, flexibilização de currículo é a proposta central da videoaula, com o intuito de atendimento para as diversidades, necessidades e interesses dos estudantes da Educação de Jovens e Adultos, com respaldo em estudos neurocientíficos. Há também a proposta de análise de currículos destinados à EJA na videoaula, com olhar direcionado para adaptações/flexibilizações. | G21: https://youtu.be/RQ0CNg-ve4s | H21: ok | I21: finalizado | J21: ok | K21: 2390P013798 | M21: 0.011643519
C22: Semana 5 | D22: AULA 11 | E22: DIFICULDADES DE APRENDIZAGEM E EDUCAÇÃO INCLUSIVA NA EDUCAÇÃO DE JOVENS E ADULTOS | F22: A videoaula propõe a reflexão sobre a definição de Educação Especial e Educação Inclusiva, abordando dificuldades de aprendizagem e possíveis práticas inclusivas na Educação de Jovens e Adultos. | G22: https://youtu.be/65VNHT6PkRo | H22: ok | I22: finalizado | J22: ok | K22: 2390P013799 | M22: 0.01556713
D23: AULA 12 | E23: Educação de Jovens e Adultos em situação de privação/restrição de liberdade | F23: A videoaula tem como propósito ampliar olhares sobre os possíveis perfis de estudantes da Educação de Jovens e Adultos e de seus contextos sociais e culturais, atentando-se para situações em que ocorrem a privação ou restrição de liberdade, ou seja, trata-se de propor reflexões sobre a escola na prisão. | G23: https://youtu.be/y-VmE4wPoZw | H23: ok | I23: finalizado | J23: ok | K23: 2390P013800 | M23: 0.012766204
D24: AULA 13 | E24: Educação de Jovens e Adultos para quilombolas, indígenas, moradores do campo e itinerantes | F24: A videoaula se dedica a continuar fomentando reflexões sobre os possíveis perfis de estudantes da Educação de Jovens e Adultos e de seus contextos sociais e culturais, voltando a atenção para a pluralidade e a visibilidade dos estudantes de EJA quilombolas, indígenas, moradores do campo e itinerantes. | G24: https://youtu.be/XO8EsahwI2I | H24: ok | I24: finalizado | J24: ok | K24: 2390P013801 | M24: 0.01755787
C25: Semana 6 | D25: AULA 14 | E25: Metodologias ativas e recursos tecnológicos na educação de jovens e adultos | G25: https://youtu.be/1wkRYohT48A | H25: ok | I25: finalizado | J25: ok | K25: 2390P013802 | M25: 0.014525463
D26: AULA 15 | E26: Avaliação na educação de jovens e adultos | G26: https://youtu.be/9_CtO6w78Uc | H26: ok | I26: finalizado | J26: ok | K26: 2390P013803 | M26: 0.014224537
C27: Semana 7 | D27: AULA 16 | E27: Projetos, ações e trocas de experiências | G27: https://youtu.be/vYZs32RQI64 | H27: ok | I27: finalizado | J27: ok | K27: 2390P013804 | M27: 0.0084837963
D28: AULA 17 | E28: A Educação de Jovens e Adultos em Ação | G28: https://youtu.be/EGKARAeSifQ | H28: ok | I28: finalizado | J28: ok | K28: 2390P015441 | M28: 0.010219907
D29: AULA 18 | E29: Formação de professores | G29: https://youtu.be/BfmK_1sWPi4 | I29: finalizado | J29: ok | K29: 2390P015452 | M29: 0.010462963
A31: CIN300 | B31: =VLOOKUP(A31,Geral!$A$1:$D$36,2,FALSE) -> Gestão de Sistemas de Informação | C31: Semana 1 | D31: AULA 0 | E31: Apresentação | G31: https://youtu.be/-vY3zo9m77E | H31: ok | I31: finalizado | J31: ok | K31: 2390P015321 | L31: 0.0016782407 | M31: =VLOOKUP(A31,Geral!$A$1:$D$36,3,FALSE) -> Antonio Francisco Savi | N31: =VLOOKUP(A31,Geral!$A$1:$D$36,4,FALSE) -> Daniel
D32: AULA 01 | E32: Conceitos básicos: dados , informação e o papel nas organizações | G32: https://youtu.be/F9QKJd3ect4 | H32: ok | I32: finalizado | J32: ok | K32: 2390P015322 | L32: 0.0082986111
D33: AULA 02 | E33: Definição e contruibuição dos sistemas de informação na gestão organizacional | G33: https://youtu.be/PNG0GLqaNPU | H33: ok | I33: finalizado | J33: ok | K33: 2390P015323 | L33: 0.012650463
D34: AULA 03 | E34: Tecnologias da informação e comunicação (TIC) nos sistemas de informação empresariais | G34: https://youtu.be/AqsiIuHEq-Q | H34: ok | I34: finalizado | J34: ok | K34: 2390P015324 | L34: 0.0087037037
C35: Semana 2 | D35: AULA 04 | E35: Sistemas de informação: identificando suas cinco áreas de conhecimento | G35: https://youtu.be/hgKN8EsZyhM | H35: ok | I35: finalizado | J35: ok | K35: 2390P015325 | L35: 0.010069444
D36: AULA 05 | E36: Tecnologias utilizadas em sistemas de informação empresariais | G36: https://youtu.be/rSDu9psovvA | H36: ok | I36: finalizado | J36: ok | K36: 2390P015326 | L36: 0.015115741
D37: AULA 06 | E37: Sistemas ERP (Enterprise Resourse Planning), SIG (sistemas de Informação Gerencial) e e-commerce | G37: https://youtu.be/8HyHD5CZews | H37: ok | I37: finalizado | J37: ok | K37: 2390P015327 | L37: 0.0085648148
C38: Semana 3 | D38: AULA 07 | E38: O papel dos sistemas de informação nas decisões empresariais | G38: https://youtu.be/7H3P9hjaaag | H38: ok | I38: finalizado | J38: ok | K38: 2390P015328 | L38: 0.0097800926
D39: AULA 08 | E39: Classificação dos sistemas de informação | G39: https://youtu.be/SEuo-OZ9HjY | H39: ok | I39: finalizado | J39: ok | K39: 2390P015329 | L39: 0.0089467593
D40: AULA 09 | E40: E-commerce nas estratégias de negócios e na gestão da cadeia de suprimentos | G40: https://youtu.be/dno20kR3vy4 | H40: ok | I40: finalizado | J40: ok | K40: 2390P015330 | L40: 0.010509259
C41: Semana 4 | D41: AULA 10 | E41: Gestão de Sistemas Seguros | G41: https://youtu.be/Sk9kAy_yjh0 | H41: ok | I41: finalizado | J41: ok | K41: 2390P015331 | L41: 0.008900463
D42: AULA 11 | E42: Segurança em várias camadas | G42: https://youtu.be/OM8SQu4TQJE | H42: ok | I42: finalizado | J42: ok | K42: 2390P015333 | L42: 0.0085532407
...

Sheet Acessibilidade
G1: TV ACESSIBILIDADE | J1: MONTAGEM
A2: Código | B2: Disciplina | C2: Semana | D2: N° de aulas | E2: Título | F2: Link Original | G2: Link Libras | H2: Link Audiodescrição | I2: Legendas REVISADAS | J2: Foi inserido no ava? | K2: Conteudista | L2: Bim
A3: FIS300 | B3: =VLOOKUP(A3,Geral!$A$1:$D$43,2,FALSE) -> Física do Movimento (Engenharia de Computação 2020.1) | C3: Semana 1 | D3: AULA 01 | E3: Tempo e relógio atômico | F3: https://youtu.be/xfvYYbW9GEo | H3: https://youtu.be/SZZnYoplAQQ | I3: ok | J3: ok | L3: =VLOOKUP(A3,Geral!A:G,7,0) -> 2024.2 AC
D4: AULA 02 | E4: Espaço, Tempo e matéria - Referências e Coordenadas | F4: https://youtu.be/vhr56G8ZtuU | H4: https://youtu.be/pOk5GaXOufM | I4: ok | J4: ok
D5: AULA 03 | E5: Algarismos significativos e Incertezas - Exercícios | F5: https://youtu.be/IMMMMnZHhOE | H5: https://youtu.be/UtMleuWiH38 | I5: ok | J5: ok
C6: Semana 2 | D6: AULA 04 | E6: Conceitos de cinemática - Parte 1 | F6: https://youtu.be/1OLBTHDqWIE | H6: https://youtu.be/zOwdV125Opg | I6: ok | J6: ok
D7: AULA 05 | E7: Conceitos de cinemática - Parte 2 | F7: https://youtu.be/XKZQotDgj64 | H7: https://youtu.be/XxHS3jneAOc | I7: ok | J7: ok
D8: AULA 06 | E8: Conceitos de cinemática - Parte 3 | F8: https://youtu.be/pZcxF2a2-qs | H8: https://youtu.be/vACNJ5yrXi0 | I8: ok | J8: ok
C9: Semana 3 | D9: AULA 07 | E9: Forças, Newton e Dinâmica | F9: https://youtu.be/2QC5iCTR8z0 | H9: https://youtu.be/qgTzmDkSAvg | I9: ok | J9: ok
D10: AULA 08 | E10: Forças | F10: https://youtu.be/GcVyR_GB1GY | H10: https://youtu.be/O0IQBqg-IfY | I10: ok | J10: ok
D11: AULA 09 | E11: Leis de Newton | F11: https://youtu.be/1fT1nVfbW-4 | H11: https://youtu.be/zIQLfrJQcBw | I11: ok | J11: ok
C12: Semana 4 | D12: AULA 10 | E12: Energia e transformação de Energia | F12: https://youtu.be/kSpLKZaW0XQ | H12: https://youtu.be/QF01omZuWkA | I12: ok | J12: ok
D13: AULA 11 | E13: Energia | F13: https://youtu.be/knhR38J1kOc | H13: https://youtu.be/dHERTiEkYes | I13: ok | J13: ok
D14: AULA 12 | E14: Energia, Potência e Conservação da Energia | F14: https://youtu.be/uqI_SgYWBYs | H14: https://youtu.be/jQH6o6PyynI | I14: ok | J14: ok
C15: Semana 5 | D15: AULA 13 | E15: Sistemas de partículas e colisões | F15: https://youtu.be/cHDO0BYTWO0 | H15: https://youtu.be/U5kalb0Mc14 | I15: ok | J15: ok
D16: AULA 14 | E16: Conservação do momento linear | F16: https://youtu.be/wiY1gEgx5x0 | H16: https://youtu.be/ec_Gyml_Emk | I16: ok | J16: ok
D17: AULA 15 | E17: Sistemas de partículas e colisões - Exemplos | F17: https://youtu.be/UgnDsZFU8Ys | H17: https://youtu.be/yz007Fxx3ts | I17: ok | J17: ok
C18: Semana 6 | D18: AULA 16 | E18: Equilíbrio | F18: https://youtu.be/n80xhVGCe1g | H18: https://youtu.be/WNWkud-yHTk | I18: ok | J18: ok
D19: AULA 17 | E19: Estruturas indeterminadas | F19: https://youtu.be/NX25B_t3FjU | H19: https://youtu.be/sxZ4Rs9Wntc | I19: ok | J19: ok
D20: AULA 18 | E20: Casos especiais | F20: https://youtu.be/EDbHjw1VbcI | H20: https://youtu.be/L0XhNOlsOkM | I20: ok | J20: ok
C21: Semana 7 | D21: AULA 19 | E21: Astronomia e Gravitação Universal | F21: https://youtu.be/7L8GfjQmRAo | H21: https://youtu.be/jgsMR7p7JoE | I21: ok | J21: ok
D22: AULA 20 | E22: Gravitação | F22: https://youtu.be/AHjQLFmXPJc | H22: https://youtu.be/N7AMgXzmkbU | I22: ok | J22: ok
D23: AULA 21 | E23: Leis de Kepler | F23: https://youtu.be/Zp1eKN0a4S4 | H23: https://youtu.be/VkmD1KdrsiQ | I23: ok | J23: ok
A25: MMB002 | B25: =VLOOKUP(A25,Geral!$A$1:$D$50,2,FALSE) -> Matemática básica | C25: Semana 1 | D25: Costurando 1 | E25: Costurando - Semana 1 | F25: https://youtu.be/D8-PdKrR-D8 | G25: https://youtu.be/DIHlOzOvEu8 | H25: https://youtu.be/Fbpwjz96iSQ | I25: ok | J25: ok | K25: =VLOOKUP(A25,Geral!$A$1:$D$50,3,FALSE) -> Prof.Rúbia Barcelos Amaral | L25: =VLOOKUP(A25,Geral!A:G,7,0) -> 2024.2 AC
D26: AULA 01 | E26: Perspectiva histórica da construção dos números e da teoria dos conjuntos | F26: https://youtu.be/iFW8gm-zoR4 | G26: https://youtu.be/2oTRIPxK2PE | H26: https://youtu.be/6_36XTd4WdU | I26: ok | J26: ok
D27: AULA 02 | E27: Noções iniciais de Conjuntos – Parte 1 | F27: https://youtu.be/yzpiMJW3CzM | G27: https://youtu.be/r2oXE6wnv3c | H27: https://youtu.be/YpEZQK_y-P4 | I27: ok | J27: ok
D28: AULA 03 | E28: Noções iniciais de Conjuntos – Parte 2 | F28: https://youtu.be/8O5K-bQQ97o | G28: https://youtu.be/2WjQIfth1iw | H28: https://youtu.be/j4VbGlaUP-o | I28: ok | J28: ok
D29: Costurando 2 | E29: Costurando - Semana 2 | F29: https://youtu.be/1rq2pdPpdmI | G29: https://youtu.be/jt8QmHb4sxI | H29: https://youtu.be/7E1UWUz4PFA | I29: ok | J29: ok
C30: Semana 2 | D30: AULA 04 | E30: Noções de Lógica | F30: https://youtu.be/I9npqB-KkSE | G30: https://youtu.be/wozD-nY2ITI | H30: https://youtu.be/MFc5mbaNtw4 | I30: ok | J30: ok
D31: AULA 05 | E31: Conjuntos numéricos – parte 1 | F31: https://youtu.be/F0c9YLIq5dU | G31: https://youtu.be/A1VO9af4rxA | H31: https://youtu.be/CsCz9-i58s8 | I31: ok | J31: ok
D32: AULA 06 | E32: Conjuntos numéricos – parte 2 | F32: https://youtu.be/VWFaoQPaxmk | G32: https://youtu.be/26zpa9b46-A | H32: https://youtu.be/undJHG0luf8 | I32: ok | J32: ok
D33: Costurando 3 | E33: Costurando - Semana 3 | F33: https://youtu.be/xdHTggX-OCA | G33: https://youtu.be/7NLioFN6vzM | H33: https://youtu.be/6y1l97oX5vI | I33: ok | J33: ok
C34: Semana 3 | D34: AULA 07 | E34: Divisibilidade | F34: https://youtu.be/gcaL43wVftc | G34: https://youtu.be/pSbMKd3Yv0k | H34: https://youtu.be/72vWt0JKPrY | I34: ok | J34: ok
D35: AULA 08 | E35: Frações | F35: https://youtu.be/HP46l0XzsEM | G35: https://youtu.be/p-uMa0XPQIc | H35: https://youtu.be/GrNFug-Ju28 | I35: ok | J35: ok
D36: Costurando 4 | E36: Costurando - Semana 4 | F36: https://youtu.be/4ZGGSvfMQPQ | G36: https://youtu.be/_nuLbDZO20c | H36: https://youtu.be/IFXHCliZkzg | I36: ok | J36: ok
D37: AULA 09 | E37: Operações com frações | F37: https://youtu.be/Koqt286csj0 | G37: https://youtu.be/ziDgbH5PC1A | H37: https://youtu.be/6uGcTooN5u4 | I37: ok | J37: ok
C38: Semana 4 | D38: AULA 10 | E38: Potenciação e Radiciação | F38: https://youtu.be/CDoENi_jWAY | G38: https://youtu.be/xMKQo5QAzAk | H38: https://youtu.be/Z-HoXmj3AZQ | I38: ok | J38: ok
D39: AULA 11 | E39: Notação científica | F39: https://youtu.be/bDVrHTuVaxM | G39: https://youtu.be/mzEXdwdWM6s | H39: https://youtu.be/0sSHxo6ot5U | I39: ok | J39: ok
D40: Costurando 5 | E40: Costurando - Semana 5 | F40: https://youtu.be/uhrlhquQQjM | G40: https://youtu.be/0scuiEF5dtE | H40: https://youtu.be/r3dCmYxuXLk | I40: ok | J40: ok
D41: AULA 12 | E41: Expressões numéricas | F41: https://youtu.be/n_rZc8IRGHM | G41: https://youtu.be/OtM4zPldSOU | H41: https://youtu.be/8-6M1HsL0Tg
...

Sheet COM100 - Marcos
A1: CÓD | B1: Disciplina | C1: Semanas | D1: Nº de aulas | E1: Título da aula | F1: Sinopse da Videoaula | G1: Link no YouTube | H1: Slide na pasta | I1: Status | J1: Download | K1: ID (TV Cultura) | L1: Duração | M1: Professor | N1: DI
C2: Semana 01 | D2: 0 | E2: Bem-Vindos! | G2: https://youtu.be/01Hb_UV-yDA | I2: finalizado | J2: ok | K2: 2390P015450 | L2: 0.011701389
D3: 1 | E3: O Século XXI e a computação na BNCC - Parte 1 | G3: https://youtu.be/GGKLbcpO_DY | H3: OK | I3: finalizado | J3: ok | K3: 2390P015436 | L3: 0.012118056
D4: 2 | E4: O Século XXI e a computação na BNCC - Parte 2 | G4: https://youtu.be/0aPzdqLQezg | H4: OK | I4: finalizado | J4: ok | K4: 2390P015437 | L4: 0.022222222
C5: MATERIAL DE APOIO | E5: Jovem Engenheiro | G5: https://youtu.be/CavGI3hojDs | I5: finalizado | J5: ok | K5: 2390E006221 | L5: 0.0081597222
C6: Semana 02 | D6: 3 | E6: Pensamento Computacional - Parte 1 | G6: https://youtu.be/L-rQmj3xMkI | H6: OK | I6: finalizado | J6: ok | K6: 2390P015438 | L6: 0.017407407
D7: 4 | E7: Pensamento Computacional - Parte 2 | G7: https://youtu.be/Ntq26PHJ-MM | I7: finalizado | J7: ok | K7: 2390P015439 | L7: 0.0077777778
D8: 5 | E8: Pensamento Computacional - Parte 3 | G8: https://youtu.be/4Z5JhJylsic | I8: finalizado | J8: ok | K8: 2390P015440 | L8: 0.0097106481
C9: MATERIAL DE APOIO | E9: A teoria na prática | G9: https://youtu.be/CM-U0bX-0kQ | H9: ( | I9: finalizado | J9: ok
C10: Semana 03 | D10: 6 | E10: Introdução ao Scracth | G10: https://youtu.be/3RW9zEiG6W4 | I10: finalizado | J10: ok | K10: 2390P015453 | L10: 0.0036342593
D11: 7 | E11: Meu primeiro programa | G11: https://youtu.be/fIlciM63TLE | H11: OK | I11: finalizado | J11: ok | K11: 2390P015454 | L11: 0.01412037
D12: 8 | E12: Estruturas de repetição | G12: https://youtu.be/AASk-CP-J88 | H12: OK | I12: finalizado | J12: ok | K12: 2390P015455 | L12: 0.011701389
C13: Semana 04 | D13: 9 | E13: Condicionais - Parte 1 | G13: https://youtu.be/Y9QwlY_GL_M | H13: OK | I13: finalizado | J13: ok | K13: 2390P015456 | L13: 0.01255787
D14: 10 | E14: Condicionais - Parte 2 | G14: https://youtu.be/McVt05VV8lo | I14: finalizado | J14: ok | K14: 2390P015457 | L14: 0.0071180556
D15: 11 | E15: Sons, falas e fantasias | G15: https://youtu.be/RcJoHOw7fbM | H15: OK | I15: finalizado | J15: ok | K15: 2390P015458 | L15: 0.0066203704
D16: 12 | E16: Variáveis | G16: https://youtu.be/Rgf9-jjrhDU | H16: OK | I16: finalizado | J16: ok | K16: 2390P015459 | L16: 0.0066435185
C17: Semana 05 | D17: 13 | E17: Explorando projetos com arte e tecnologia no scracth | G17: https://youtu.be/7e7RgvT5zUw | I17: finalizado | J17: ok | K17: 2390P015460 | L17: 0.010717593
D18: 14 | E18: Remixando projetos no scracth | G18: https://youtu.be/yteOg2jkoV0 | I18: finalizado | J18: ok | K18: 2390P015461
C19: Semana 06 | D19: 15 | E19: Criando projetos autorais | G19: https://youtu.be/Y8Nogbn5ksw | I19: finalizado | J19: ok | K19: 2390P015462 | L19: 0.010277778
D20: 16 | E20: Criando projetos autorais com uso de extensão | G20: https://youtu.be/7gJktl2k97s | I20: finalizado | J20: ok | K20: 2390P015463 | L20: 0.011701389
C21: Semana 07 | D21: 17 | E21: Conteúdo digital e inteligência artificial - Parte 1 | G21: https://youtu.be/HLgWwXI5fWo | H21: OK | I21: finalizado | J21: ok | K21: 2390P015508
D22: 18 | E22: Conteúdo digital e inteligência artificial - Parte 2 | G22: https://youtu.be/17dEbecypfE | H22: OK | I22: finalizado | J22: ok | K22: 2390P015509
D23: 19 | E23: Conteúdo digital e inteligência artificial - Parte 3 | G23: https://youtu.be/CvSbIY4f0GU | H23: OK | I23: finalizado | J23: ok | K23: 2390P015510
D24: 20 | E24: Conteúdo digital e inteligência artificial - Parte 4 | G24: https://youtu.be/S5B31VYLlLA | H24: OK | I24: finalizado | J24: ok | K24: 2390P015511
D25: 21 | E25: Conteúdo digital e inteligência artificial - Parte 5 | G25: https://youtu.be/YFjqnRr00GA | H25: OK | I25: finalizado | J25: ok | K25: 2390P015512
D26: 22 | E26: Conteúdo digital e inteligência artificial - Parte 6 | G26: https://youtu.be/GtFf8ZZYVE4 | H26: OK | I26: finalizado | J26: ok | K26: 2390P015513
D27: 23 | E27: Conteúdo digital e inteligência artificial - Parte 7 | G27: https://youtu.be/-f27KPLQeHs | H27: OK | I27: finalizado | J27: ok | K27: 2390P015514

Sheet Tutorial Univesp 2024
A1: Título da aula | B1: Link no YouTube | C1: ID BRUTO | D1: Duração
A2: Login com E-mail Univesp | B2: https://youtu.be/IBXjbB0yzrA | C2: 2390B013428 | D2: 0.0021643519
A3: E-mail Univesp | B3: https://youtu.be/RhX9z4-pN1E | C3: 2390B013429 | D3: 0.0022222222
A4: Login Teams | B4: https://youtu.be/_G4Bd76P7Dc | C4: 2390B013430 | D4: 0.0023032407
A5: Teams Informativo | B5: https://youtu.be/iaJGjWHId8o | C5: 2390B013431 | D5: 0.0012962963
A6: Teams Tutoriais | B6: https://youtu.be/2fB5eRH3W0o | C6: 2390B013432 | D6: 0.0017476852
A7: Atendimento | B7: https://youtu.be/T3PoVJPss3Y | C7: 2390B013433 | D7: 0.0023263889
A8: Formulários | B8: https://youtu.be/HGK3z-3eVPo | C8: 2390B013434 | D8: 0.0022453704
A9: AVA | B9: https://youtu.be/GIlup20xHLE | C9: 2390B013435 | D9: 0.0031365741
A10: Manual do Aluno | B10: https://youtu.be/YPA623GUF48 | C10: 2390B013436 | D10: 0.0023726852
A11: Atividades das Equipes | B11: https://youtu.be/DfuQpwWk6iE | C11: 2390B013437/2390B013438 | D11: 0.0049884259
A12: Acessos as Plataformas SEI - Provas | B12: https://youtu.be/KiEM9XylOaA | C12: 2390B013460 | D12: 0.0030902778
A13: Bloqueio de Provas | B13: https://youtu.be/8cHORvaq_gc | C13: 2390B013461 | D13: 0.0021296296
... A31: consulta aluno | B31: https://youtu.be/6Dl5-dXFDXk | C31: 2390B013606 | D31: 0.0015625

Sheet Quem Sabe, Ganha!
A1: Episódio | B1: ID YOUTUBE / APP | C1: duração | D1: data postagem | E1: Link no YouTube | F1: Disponivel no app
A2: QUEM SABE, GANHA - 01 - BORBOREMA X VARGEM GRANDE PAULISTA | B2: 3147P000041 | C2: 0.031909722 | D2: 6-jun. | E2: https://youtu.be/7VFatHn2_6M | F2: SIM
A5: QUEM SABE, GANHA - 02 - SERTÃOZINHO X SANTANA DE PARNAÍBA | B5: 3147P000046 | C5: 0.031203704 | D5: 13-jun. | E5: https://youtu.be/7910pqXDncA | F5: SIM
A8: QUEM SABE, GANHA - 03 - GUARUJÁ X SÃO BERNARDO DO CAMPO | B8: 3147P000049 | C8: 0.031701389 | D8: 20-jun. | E8: https://youtu.be/PDvOG5yg9UQ | F8: SIM
A11: QUEM SABE, GANHA - 04 - MIRANTE DO PARANAPANEMA X ITAPECERICA DA SERRA | B11: 3147P000045 | C11: 0.031365741 | D11: 27-jun. | E11: https://youtu.be/sm99pV6zXOY | F11: SIM
A14: QUEM SABE, GANHA - 05 - POÁ X ITAQUAQUECETUBA | B14: 3147P000051 | C14: 0.030729167 | D14: 4-jul. | E14: https://youtu.be/DD57NZJVyX4 | F14: SIM
A17: QUEM SABE, GANHA - 06 - ITÁPOLIS X FRANCA | B17: 3147P000044 | C17: 0.031064815 | D17: 11-jul. | E17: https://youtu.be/oLKdX7vxhMo | F17: SIM
A20: QUEM SABE, GANHA - 07 - IGARAPAVA X CLEMENTINA | B20: 3147P000040 | C20: 0.03099537 | D20: 18-jul. | E20: https://youtu.be/Fzc2aGIAGFs | F20: SIM
A23: QUEM SABE, GANHA - 08 - TUPÃ X POÁ | B23: 3147P000050 | C23: 0.030833333 | D23: 25-jul. | E23: https://youtu.be/d9yq1KVc1vE | F23: SIM
A26: QUEM SABE, GANHA - 09 - CAJURU X SÃO PAULO | B26: 3147P000042 | C26: 0.031215278 | D26: 1-ago. | E26: https://youtu.be/W2Mdy_oox1o | F26: SIM
A29: QUEM SABE, GANHA - 10 - ITAPECERICA DA SERRA X ITAPETININGA | B29: 3147P000048 | C29: 0.03119213 | D29: 8-ago. | E29: https://youtu.be/b2mRlLOrGLY | F29: SIM
A32: QUEM SABE, GANHA - 11 - BARÃO DE ANTONINA X SÃO PAULO | B32: 3147P000043 | C32: 0.031145833 | D32: 15-ago. | E32: https://youtu.be/huNyTWmg78o | F32: SIM
A35: QUEM SABE, GANHA - 12 - OSASCO X SÃO PAULO | B35: 3147P000047 | C35: 0.030972222 | D35: 22-ago. | E35: https://youtu.be/LZ3LVdaBDFg | F35: SIM
A38: QUEM SABE, GANHA - 13 - SÃO JOSÉ DOS CAMPOS X ITAPECERICA DA SERRA | B38: 3147P000052 | C38: 0.030983796 | D38: 29-ago. | E38: https://youtu.be/5QfqzH9OAec | F38: SIM

Sheet Disciplina Paulista de Acessib.
A1: Disciplina | B1: Semanas | C1: Nº de aulas | D1: Título da aula | E1: Sinopse da Videoaula | F1: Link no YouTube | G1: Slide na pasta | H1: Status | I1: Download | J1: ID LIBRAS | K1: Link LIBRAS | L1: Duração | M1: ID AUDIODESCRIÇÃO | N1: Link AD | O1: Professor | P1: DI
A2: Disciplina Paulista de Acessibilidade | C2: 1 | D2: Introdução e Apresentação da Disciplina | G2: ok | J2: 3164P000129 | K2: https://youtu.be/YHjL_xmN7go | L2: 0.67569444 | M2: 3164P000059 | N2: https://youtu.be/E69-DYsTaeM
C3: 2 | D3: Museu da Inclusão | G3: ok | J3: 3164P000121 | K3: https://youtu.be/RrzX_5Vx2IQ | M3: 3164P000060 | N3: https://youtu.be/1CU4Rd9_2lI
C4: 3 | D4: Evolução do Conhecimento da População sobre Deficiência Intelectual (Univesp 2024). | G4: ok | J4: 3164P000102 | K4: https://youtu.be/BcQO8uChjcY | L4: 0.39791667 | M4: 3164P000061 | N4: https://youtu.be/RP3R_Qp9e6I
C5: 4 | D5: Entrevista com Professor Doutor Clodoaldo Meneguello Cardoso | G5: ok | J5: 3164P000130 | K5: https://youtu.be/0XELkbdzp3k | M5: 3164P000062 | N5: https://youtu.be/TWzBDvUeXxY
C6: 5 | D6: Fundamentos históricos legais e concetuais da inclusão | J6: 3164P000104 | K6: https://youtu.be/snq5ipWlj4M | L6: 0.87430556 | M6: 3164P000063 | N6: https://youtu.be/O4HhvFeTIes
C7: 6 | D7: Entrevista com Professora Doutora Carla Biancha Angelucci | J7: 3164P000137 | K7: https://youtu.be/UI_zMgoLByc | M7: 3164P000064 | N7: https://youtu.be/VrVaiYfXPHU
C8: 7 | D8: Deficiência e capacitismo | J8: 3164P000106 | K8: https://youtu.be/BTyL_GXwaV4 | M8: 3164P000065 | N8: https://youtu.be/_ukBwx-M7-Q
C9: 8 | D9: Entrevista com Professor Especialista Ivan de Oliveira Freitas | G9: ok | J9: 3164P000107 | K9: https://youtu.be/T9ccWdju7AQ | M9: 3164P000066 | N9: https://youtu.be/vxd1fGoj5eU
C10: 9 | D10: Entrevista com Professor Doutor Honoris Causa Marcos da Costa, Secretário de Estado dos Direitos da Pessoa com Deficiência. | G10: ok | J10: 3164P000131 | K10: https://youtu.be/imFYu-lUMXY | M10: 3164P000067 | N10: https://youtu.be/5vK8_kUacn8
C11: 10 | D11: Univesp por Elas - Entrevista com Cláudia Carletto | G11: ok | J11: 3164P000122 | K11: https://youtu.be/TB-8CxPeDgE | M11: 3164P000068 | N11: https://youtu.be/bVGpA-9SH-I
C12: 11 | D12: Acessibilidade | G12: ok | J12: 3164P000109 | K12: https://youtu.be/okfKyMM8vm0 | M12: 3164P000069 | N12: https://youtu.be/zK9Mdu5Yfs4
C13: 12 | D13: Videoaula animada: Dimensões da Acessibilidade Parte I | G13: ok | J13: 3164P000024 | K13: https://youtu.be/u3sntETrLQw | M13: 3164P000070 | N13: https://youtu.be/H8BLLgcpNzw
C14: 13 | D14: Videoaula animada: Dimensões da Acessibilidade Parte II | G14: ok | J14: 3164P000026 | K14: https://youtu.be/Cgvj-ujsuiw | M14: 3164P000071 | N14: https://youtu.be/vFB80FG0caE
C15: 14 | D15: Entrevista com Professora Doutora Anna Maria Lunardi Padilha | G15: ok | J15: 3164P000132 | K15: https://youtu.be/mnMio2DM_V8 | M15: 3164P000072 | N15: https://youtu.be/iCC2qKgBcZ0
C16: 15 | D16: Fala Doutor - Cássia Geciauskas Sofiato: Do desenho à litografia - PGM 18 (2012) | G16: ok | J16: 3164P000030 | K16: https://youtu.be/a3gFtcFS8_c | M16: 3164P000073 | N16: https://youtu.be/Mx5V-txH-CA
C17: 16 | D17: Entrevista com Professora Doutora Lígia Rodrigues Balista | G17: ok | J17: 3164P000133 | K17: https://youtu.be/sp0wbwJ2R-U | M17: 3164P000074 | N17: https://youtu.be/E6rMzM-l25E
C18: 17 | D18: Conhecimento da população sobre LIBRAS (2024) | G18: ok | J18: 3164P000124 | K18: https://youtu.be/nPzZ-4E6uBk | M18: 3164P000125 | N18: https://youtu.be/-M_vNKTvfo0
C19: 18 | D19: Tecnologia assistiva | G19: ok | J19: 3164P000113 | K19: https://youtu.be/b36gH-yYGtg | M19: 3164P000076 | N19: https://youtu.be/J3dk4pYSTrg
C20: 19 | D20: D-30 - A tecnologia na Educação Inclusiva | G20: ok | J20: 3164P000038 | K20: https://youtu.be/qunN5PqZblI | M20: 3164P000077 | N20: https://youtu.be/s0BK3eTMQhA
... C26: 25 | D26: Ampliando conhecimentos sobre acessibilidade e inclusão | G26: ok | J26: 3164P000119 | K26: https://youtu.be/Hq4e6t6fhHw | M26: 3164P000083 | N26: https://youtu.be/E54aFmKBKVY
C27: 26 | D27: Entrevista com Professora Mestra Aldine Nogueira da Silva | G27: ok | K27: https://youtu.be/2l76ukmTN0A | M27: 3164P000084 | N27: https://youtu.be/9s5wlJSMQlA
C28: 27 | D28: Entrevista com Professora Doutora Cristina Bressaglia Lucon | G28: ok | J28: 3164P000054 | K28: https://youtu.be/PzT8jxsEtwk | M28: 3164P000085 | N28: https://youtu.be/6R-cnO1WTs8
